nohup: ignoring input
/home/chy63/.conda/envs/openflamingo/lib/python3.9/site-packages/torchvision/datapoints/__init__.py:12: UserWarning: The torchvision.datapoints and torchvision.transforms.v2 namespaces are still Beta. While we do not expect major breaking changes, some APIs may still change according to user feedback. Please submit any feedback you may have in this issue: https://github.com/pytorch/vision/issues/6753, and you can also check out https://github.com/pytorch/vision/issues/7319 to learn more about the APIs that we suspect might involve future changes. You can silence this warning by calling torchvision.disable_beta_transforms_warning().
  warnings.warn(_BETA_TRANSFORMS_WARNING)
/home/chy63/.conda/envs/openflamingo/lib/python3.9/site-packages/torchvision/transforms/v2/__init__.py:54: UserWarning: The torchvision.datapoints and torchvision.transforms.v2 namespaces are still Beta. While we do not expect major breaking changes, some APIs may still change according to user feedback. Please submit any feedback you may have in this issue: https://github.com/pytorch/vision/issues/6753, and you can also check out https://github.com/pytorch/vision/issues/7319 to learn more about the APIs that we suspect might involve future changes. You can silence this warning by calling torchvision.disable_beta_transforms_warning().
  warnings.warn(_BETA_TRANSFORMS_WARNING)
2024-10-31 11:54:37,016 - INFO - Loading pretrained ViT-L-14 from OpenAI.
Traceback (most recent call last):
  File "/home/chy63/.conda/envs/openflamingo/lib/python3.9/site-packages/urllib3/connection.py", line 196, in _new_conn
    sock = connection.create_connection(
  File "/home/chy63/.conda/envs/openflamingo/lib/python3.9/site-packages/urllib3/util/connection.py", line 85, in create_connection
    raise err
  File "/home/chy63/.conda/envs/openflamingo/lib/python3.9/site-packages/urllib3/util/connection.py", line 73, in create_connection
    sock.connect(sa)
OSError: [Errno 101] Network is unreachable

The above exception was the direct cause of the following exception:

Traceback (most recent call last):
  File "/home/chy63/.conda/envs/openflamingo/lib/python3.9/site-packages/urllib3/connectionpool.py", line 789, in urlopen
    response = self._make_request(
  File "/home/chy63/.conda/envs/openflamingo/lib/python3.9/site-packages/urllib3/connectionpool.py", line 490, in _make_request
    raise new_e
  File "/home/chy63/.conda/envs/openflamingo/lib/python3.9/site-packages/urllib3/connectionpool.py", line 466, in _make_request
    self._validate_conn(conn)
  File "/home/chy63/.conda/envs/openflamingo/lib/python3.9/site-packages/urllib3/connectionpool.py", line 1095, in _validate_conn
    conn.connect()
  File "/home/chy63/.conda/envs/openflamingo/lib/python3.9/site-packages/urllib3/connection.py", line 615, in connect
    self.sock = sock = self._new_conn()
  File "/home/chy63/.conda/envs/openflamingo/lib/python3.9/site-packages/urllib3/connection.py", line 211, in _new_conn
    raise NewConnectionError(
urllib3.exceptions.NewConnectionError: <urllib3.connection.HTTPSConnection object at 0x7f8d0c1aa580>: Failed to establish a new connection: [Errno 101] Network is unreachable

The above exception was the direct cause of the following exception:

Traceback (most recent call last):
  File "/home/chy63/.conda/envs/openflamingo/lib/python3.9/site-packages/requests/adapters.py", line 667, in send
    resp = conn.urlopen(
  File "/home/chy63/.conda/envs/openflamingo/lib/python3.9/site-packages/urllib3/connectionpool.py", line 843, in urlopen
    retries = retries.increment(
  File "/home/chy63/.conda/envs/openflamingo/lib/python3.9/site-packages/urllib3/util/retry.py", line 519, in increment
    raise MaxRetryError(_pool, url, reason) from reason  # type: ignore[arg-type]
urllib3.exceptions.MaxRetryError: HTTPSConnectionPool(host='huggingface.co', port=443): Max retries exceeded with url: /anas-awadalla/mpt-7b/resolve/main/config.json (Caused by NewConnectionError('<urllib3.connection.HTTPSConnection object at 0x7f8d0c1aa580>: Failed to establish a new connection: [Errno 101] Network is unreachable'))

During handling of the above exception, another exception occurred:

Traceback (most recent call last):
  File "/home/chy63/.local/lib/python3.9/site-packages/huggingface_hub/file_download.py", line 1722, in _get_metadata_or_catch_error
    metadata = get_hf_file_metadata(url=url, proxies=proxies, timeout=etag_timeout, headers=headers)
  File "/home/chy63/.local/lib/python3.9/site-packages/huggingface_hub/utils/_validators.py", line 114, in _inner_fn
    return fn(*args, **kwargs)
  File "/home/chy63/.local/lib/python3.9/site-packages/huggingface_hub/file_download.py", line 1645, in get_hf_file_metadata
    r = _request_wrapper(
  File "/home/chy63/.local/lib/python3.9/site-packages/huggingface_hub/file_download.py", line 372, in _request_wrapper
    response = _request_wrapper(
  File "/home/chy63/.local/lib/python3.9/site-packages/huggingface_hub/file_download.py", line 395, in _request_wrapper
    response = get_session().request(method=method, url=url, **params)
  File "/home/chy63/.conda/envs/openflamingo/lib/python3.9/site-packages/requests/sessions.py", line 589, in request
    resp = self.send(prep, **send_kwargs)
  File "/home/chy63/.conda/envs/openflamingo/lib/python3.9/site-packages/requests/sessions.py", line 703, in send
    r = adapter.send(request, **kwargs)
  File "/home/chy63/.local/lib/python3.9/site-packages/huggingface_hub/utils/_http.py", line 66, in send
    return super().send(request, *args, **kwargs)
  File "/home/chy63/.conda/envs/openflamingo/lib/python3.9/site-packages/requests/adapters.py", line 700, in send
    raise ConnectionError(e, request=request)
requests.exceptions.ConnectionError: (MaxRetryError("HTTPSConnectionPool(host='huggingface.co', port=443): Max retries exceeded with url: /anas-awadalla/mpt-7b/resolve/main/config.json (Caused by NewConnectionError('<urllib3.connection.HTTPSConnection object at 0x7f8d0c1aa580>: Failed to establish a new connection: [Errno 101] Network is unreachable'))"), '(Request ID: dda3fd56-e792-4f37-89ce-910ee9922c14)')

The above exception was the direct cause of the following exception:

Traceback (most recent call last):
  File "/home/chy63/.conda/envs/openflamingo/lib/python3.9/site-packages/transformers/utils/hub.py", line 403, in cached_file
    resolved_file = hf_hub_download(
  File "/home/chy63/.local/lib/python3.9/site-packages/huggingface_hub/utils/_validators.py", line 114, in _inner_fn
    return fn(*args, **kwargs)
  File "/home/chy63/.local/lib/python3.9/site-packages/huggingface_hub/file_download.py", line 1221, in hf_hub_download
    return _hf_hub_download_to_cache_dir(
  File "/home/chy63/.local/lib/python3.9/site-packages/huggingface_hub/file_download.py", line 1325, in _hf_hub_download_to_cache_dir
    _raise_on_head_call_error(head_call_error, force_download, local_files_only)
  File "/home/chy63/.local/lib/python3.9/site-packages/huggingface_hub/file_download.py", line 1826, in _raise_on_head_call_error
    raise LocalEntryNotFoundError(
huggingface_hub.utils._errors.LocalEntryNotFoundError: An error happened while trying to locate the file on the Hub and we cannot find the requested files in the local cache. Please check your connection and try again or make sure your Internet connection is on.

The above exception was the direct cause of the following exception:

Traceback (most recent call last):
  File "/data/chy/online/ImageNet/main.py", line 71, in <module>
    model, image_processor, tokenizer = create_model_and_transforms(
  File "/data/chy/online/open_flamingo_v2/open_flamingo/src/factory.py", line 58, in create_model_and_transforms
    text_tokenizer = AutoTokenizer.from_pretrained(
  File "/home/chy63/.conda/envs/openflamingo/lib/python3.9/site-packages/transformers/models/auto/tokenization_auto.py", line 877, in from_pretrained
    config = AutoConfig.from_pretrained(
  File "/home/chy63/.conda/envs/openflamingo/lib/python3.9/site-packages/transformers/models/auto/configuration_auto.py", line 1017, in from_pretrained
    config_dict, unused_kwargs = PretrainedConfig.get_config_dict(pretrained_model_name_or_path, **kwargs)
  File "/home/chy63/.conda/envs/openflamingo/lib/python3.9/site-packages/transformers/configuration_utils.py", line 574, in get_config_dict
    config_dict, kwargs = cls._get_config_dict(pretrained_model_name_or_path, **kwargs)
  File "/home/chy63/.conda/envs/openflamingo/lib/python3.9/site-packages/transformers/configuration_utils.py", line 633, in _get_config_dict
    resolved_config_file = cached_file(
  File "/home/chy63/.conda/envs/openflamingo/lib/python3.9/site-packages/transformers/utils/hub.py", line 446, in cached_file
    raise EnvironmentError(
OSError: We couldn't connect to 'https://huggingface.co' to load this file, couldn't find it in the cached files and it looks like anas-awadalla/mpt-7b is not the path to a directory containing a file named config.json.
Checkout your internet connection or see how to run the library in offline mode at 'https://huggingface.co/docs/transformers/installation#offline-mode'.
